<?xml version="1.0" encoding="utf-8"?>
<!-- This URDF was automatically created by SolidWorks to URDF Exporter! Originally created by Stephen Brawner (brawner@gmail.com) 
     Commit Version: 1.6.0-4-g7f85cfe  Build Version: 1.6.7995.38578
     For more information, please see http://wiki.ros.org/sw_urdf_exporter -->
<robot
  name="ranger_mini">
  <link
    name="base_link">
    <inertial>
      <origin
        xyz="-0.0242698272228022 -0.0030308024613212 0.0544267444673498"
        rpy="0 0 0" />
      <mass
        value="0.162715996120322" />
      <inertia
        ixx="0.000723700192916944"
        ixy="-1.55745142682799E-08"
        ixz="-3.42378773027466E-12"
        iyy="0.000744046536331603"
        iyz="2.24935144207573E-07"
        izz="2.14412578189702E-05" />
    </inertial>
    <visual>
      <origin
        xyz="0 0 0"
        rpy="0 0 0" />
      <geometry>
        <mesh
          filename="package://ranger_mini_v2/meshes/ranger_base.dae" />
      </geometry>
      <material
        name="">
        <color
          rgba="0.792156862745098 0.819607843137255 0.933333333333333 1" />
      </material>
    </visual>
    <collision>
      <origin
        xyz="0 0 0"
        rpy="0 0 0" />
      <geometry>
        <mesh
          filename="package://ranger_mini_v2/meshes/ranger_base.dae" />
      </geometry>
    </collision>
  </link>
  <link
    name="fr_Link">
    <inertial>
      <origin
        xyz="1.8493E-05 1.2713E-06 0.043679"
        rpy="0 0 0" />
      <mass
        value="2.2786" />
      <inertia
        ixx="0.0063625"
        ixy="-1.0581E-07"
        ixz="-4.0831E-07"
        iyy="0.006363"
        iyz="-3.4944E-08"
        izz="0.010465" />
    </inertial>
    <visual>
      <origin
        xyz="0 0 0"
        rpy="0 0 0" />
      <geometry>
        <mesh
          filename="package://ranger_mini_v2/meshes/fr_Link.STL" />
      </geometry>
      <material
        name="">
        <color
          rgba="0.79216 0.81961 0.93333 1" />
      </material>
    </visual>
    <collision>
      <origin
        xyz="0 0 0"
        rpy="0 0 0" />
      <geometry>
        <mesh
          filename="package://ranger_mini_v2/meshes/fr_Link.STL" />
      </geometry>
    </collision>
  </link>
  <joint
    name="rl_joint"
    type="continuous">
    <origin
      xyz="0.2195 -0.015804 0.11898"
      rpy="0 0.006858 0" />
    <parent
      link="base_link" />
    <child
      link="fr_Link" />
    <axis
      xyz="0 0 -1" />
  </joint>
  <link
    name="fl_Link">
    <inertial>
      <origin
        xyz="-0.0017956 -9.6304E-08 0.043642"
        rpy="0 0 0" />
      <mass
        value="2.2786" />
      <inertia
        ixx="0.0063695"
        ixy="-2.1067E-08"
        ixz="-0.00016867"
        iyy="0.006363"
        iyz="-1.0301E-08"
        izz="0.010458" />
    </inertial>
    <visual>
      <origin
        xyz="0 0 0"
        rpy="0 0 0" />
      <geometry>
        <mesh
          filename="package://ranger_mini_v2/meshes/fl_Link.STL" />
      </geometry>
      <material
        name="">
        <color
          rgba="0.79216 0.81961 0.93333 1" />
      </material>
    </visual>
    <collision>
      <origin
        xyz="0 0 0"
        rpy="0 0 0" />
      <geometry>
        <mesh
          filename="package://ranger_mini_v2/meshes/fl_Link.STL" />
      </geometry>
    </collision>
  </link>
  <joint
    name="fl_joint"
    type="continuous">
    <origin
      xyz="0.22145 -0.015803 -0.16276"
      rpy="3.1416 0 0" />
    <parent
      link="base_link" />
    <child
      link="fl_Link" />
    <axis
      xyz="0.041054 0 -0.99916" />
  </joint>
  <link
    name="br_Link">
    <inertial>
      <origin
        xyz="-0.00017093 6.1255E-08 0.043678"
        rpy="0 0 0" />
      <mass
        value="2.2786" />
      <inertia
        ixx="0.0063627"
        ixy="-2.1069E-08"
        ixz="-1.587E-05"
        iyy="0.006363"
        iyz="9.3201E-09"
        izz="0.010465" />
    </inertial>
    <visual>
      <origin
        xyz="0 0 0"
        rpy="0 0 0" />
      <geometry>
        <mesh
          filename="package://ranger_mini_v2/meshes/br_Link.STL" />
      </geometry>
      <material
        name="">
        <color
          rgba="0.79216 0.81961 0.93333 1" />
      </material>
    </visual>
    <collision>
      <origin
        xyz="0 0 0"
        rpy="0 0 0" />
      <geometry>
        <mesh
          filename="package://ranger_mini_v2/meshes/br_Link.STL" />
      </geometry>
    </collision>
  </link>
  <joint
    name="br_joint"
    type="continuous">
    <origin
      xyz="-0.27015 -0.015803 0.12117"
      rpy="0 0 0" />
    <parent
      link="base_link" />
    <child
      link="br_Link" />
    <axis
      xyz="0.0039668 0 -0.99999" />
  </joint>
  <link
    name="bl_Link">
    <inertial>
      <origin
        xyz="-0.0011575 -4.8644E-06 0.043663"
        rpy="0 0 0" />
      <mass
        value="2.2786" />
      <inertia
        ixx="0.0063656"
        ixy="-8.1498E-08"
        ixz="-0.00011049"
        iyy="0.006363"
        iyz="6.6847E-08"
        izz="0.010462" />
    </inertial>
    <visual>
      <origin
        xyz="0 0 0"
        rpy="0 0 0" />
      <geometry>
        <mesh
          filename="package://ranger_mini_v2/meshes/bl_Link.STL" />
      </geometry>
      <material
        name="">
        <color
          rgba="0.79216 0.81961 0.93333 1" />
      </material>
    </visual>
    <collision>
      <origin
        xyz="0 0 0"
        rpy="0 0 0" />
      <geometry>
        <mesh
          filename="package://ranger_mini_v2/meshes/bl_Link.STL" />
      </geometry>
    </collision>
  </link>
  <joint
    name="bl_joint"
    type="continuous">
    <origin
      xyz="-0.26982 -0.01581 -0.16063"
      rpy="-3.1405 -0.014946 0.086503" />
    <parent
      link="base_link" />
    <child
      link="bl_Link" />
    <axis
      xyz="0.027043 0 -0.99963" />
  </joint>
</robot>