<?xml version="1.0"?>

<robot name="ranger_mini" xmlns:xacro="http://ros.org/wiki/xacro">
 <link name="base_footprint"/>

  <joint name="base_joint" type="fixed">
    <parent link="base_footprint"/>
    <child link="base_link"/>
    <origin xyz="0.0 0.0 0.15" rpy="0 0 0"/>
  </joint>

    <!-- Base link -->
    <link name="base_link">
        <visual>
            <origin xyz="0 0 0" rpy="1.57 0 3.14 " />
            <geometry>
                <mesh filename="file://$(find ranger_mini)/meshes/ranger_base.dae" />
            </geometry>
        </visual>
        <collision>
            <origin xyz="0 0 0.008" rpy="0 0 0" />
            <geometry>
                <box size="0.5 0.5 0.5"/>
            </geometry>
        </collision>
    </link>

        <!-- <link name="fl_wheel_link">
            <inertial>
                <mass value="8" />
                <origin xyz="0 0 0" />
                <inertia ixx="0.1171" ixy="0" ixz="0" iyy="0.1361" iyz="0" izz="0.1171" />
            </inertial>
            <visual>
                <origin xyz="0.23 -0.2 0.1" rpy="1.57 0 0" />
                <geometry>
                    <mesh filename="file://$(find ranger_mini)/meshes/fr.dae" />
                </geometry>
            </visual>
            <collision>
                <origin xyz="0 0 0" rpy="0 0 0" />
                <geometry>
                    <cylinder length="0.1" radius="0.1" />
                </geometry>
                     <contact>
                         <ode>
                        <min_depth>0.001</min_depth>
                         </ode>
                    </contact>
            </collision>
        </link>

        <joint name="fl_wheel" type="continuous">
            <origin xyz="0.23 0.206 -0.1" rpy="0 0 0" />
            <parent link="base_link"/>
            <child link="fl_wheel_link"/>
            <axis xyz="0 0 1" rpy="0 0 0" />
        </joint> -->

        <link name="fr_wheel_link">
            <inertial>
                <mass value="8" />
                <origin xyz="0 0 0" />
                <inertia ixx="0.1171" ixy="0" ixz="0" iyy="0.1361" iyz="0" izz="0.1171" />
            </inertial>
            <visual>
                <origin xyz="0.23 0.2 0.1" rpy="1.57 0 0" />
                <geometry>
                    <mesh filename="file://$(find ranger_mini)/meshes/fl.dae" />
                </geometry>
            </visual>
            <collision>
                <origin xyz="0 0 0" rpy="0 0 0" />
                <geometry>
                    <cylinder length="0.1" radius="0.1" />
                </geometry>
                     <!-- <contact>
                         <ode>
                        <min_depth>0.001</min_depth>
                         </ode>
                    </contact> -->
            </collision>
        </link>

        <joint name="fr_wheel" type="fixed">
            <origin xyz="0.23 -0.206 -0.1" rpy="0 0 0" />
            <parent link="base_link"/>
            <child link="fr_wheel_link"/>
            <axis xyz="0 0 1" rpy="0 0 0" />
        </joint>


        <link name="rl_wheel_link">
            <inertial>
                <mass value="8" />
                <origin xyz="0 0 0" />
                <inertia ixx="0.1171" ixy="0" ixz="0" iyy="0.1361" iyz="0" izz="0.1171" />
            </inertial>
            <visual>
                <origin xyz="0.23 -0.2 0.1" rpy="1.57 0 0" />
                <geometry>
                    <mesh filename="file://$(find ranger_mini)/meshes/fr.dae" />
                </geometry>
            </visual>
            <collision>
                <origin xyz="0 0 0" rpy="0 0 0" />
                <geometry>
                    <cylinder length="0.1" radius="0.1" />
                </geometry>
                     <!-- <contact>
                         <ode>
                        <min_depth>0.001</min_depth>
                         </ode>
                    </contact> -->
            </collision>
        </link>

        <joint name="rl_wheel" type="continuous">
            <origin xyz="-0.23 0.206 -0.1" rpy="0 0 0" />
            <parent link="base_link"/>
            <child link="rl_wheel_link"/>
            <axis xyz="0 0 1" rpy="0 0 0" />
        </joint>

        <link name="rr_wheel_link">
            <inertial>
                <mass value="8" />
                <origin xyz="0 0 0" />
                <inertia ixx="0.1171" ixy="0" ixz="0" iyy="0.1361" iyz="0" izz="0.1171" />
            </inertial>
            <visual>
                <origin xyz="0.23 0.2 0.1" rpy="1.57 0 0" />
                <geometry>
                    <mesh filename="file://$(find ranger_mini)/meshes/fl.dae" />
                </geometry>
            </visual>
            <collision>
                <origin xyz="0 0 0" rpy="0 0 0" />
                <geometry>
                    <cylinder length="0.1" radius="0.1" />
                </geometry>
                     <!-- <contact>
                         <ode>
                        <min_depth>0.001</min_depth>
                         </ode>
                    </contact> -->
            </collision>
        </link>

        <joint name="rr_wheel" type="continuous">
            <origin xyz="-0.23 -0.206 -0.1" rpy="0 0 0" />
            <parent link="base_link"/>
            <child link="rr_wheel_link"/>
            <axis xyz="0 0 1" rpy="0 0 0" />
        </joint>

   <gazebo reference="fl_wheel_link">
        <mu1>100</mu1>
        <mu2>100</mu2>
        <kp>10000000.0</kp>
        <kd>1.0</kd>
        <minDepth>0.01</minDepth>
        <fdir1>1 0 0</fdir1>
        <maxContacts value="64"/>
    </gazebo>
    <gazebo reference="fr_wheel_link">
        <mu1>100</mu1>
        <mu2>100</mu2>
        <kp>10000000.0</kp>
        <kd>1.0</kd>
        <minDepth>0.01</minDepth>
        <fdir1>1 0 0</fdir1>
        <maxContacts value="64"/>
    </gazebo>
    <gazebo reference="rl_wheel_link">
        <mu1>100</mu1>
        <mu2>100</mu2>
        <kp>10000000.0</kp>
        <kd>1.0</kd>
        <minDepth>0.01</minDepth>
        <fdir1>1 0 0</fdir1>
        <maxContacts value="64"/>
    </gazebo>
    <gazebo reference="rr_wheel_link">
        <mu1>100</mu1>
        <mu2>100</mu2>
        <kp>10000000.0</kp>
        <kd>1.0</kd>
        <minDepth>0.01</minDepth>
        <fdir1>1 0 0</fdir1>
        <maxContacts value="64"/>
    </gazebo>
<!-- 
<gazebo>
<plugin name='skid_steer_drive' filename='libgazebo_ros_diff_drive.so'>
        <ros>
          <namespace>/ranger_mini</namespace>
        </ros>

        <update_rate>500</update_rate>
        <num_wheel_pairs>2</num_wheel_pairs>

        <left_joint>fl_wheel_link</left_joint>
        <right_joint>fr_wheel_link</right_joint>

        <left_joint>rl_wheel_link</left_joint>
        <right_joint>rr_wheel_link</right_joint>

        <wheel_separation>1.25</wheel_separation>
        <wheel_separation>1.25</wheel_separation>

        <wheel_diameter>1.0</wheel_diameter>
        <wheel_diameter>0.6</wheel_diameter>

        <max_wheel_torque>20</max_wheel_torque>
        <max_wheel_acceleration>1.0</max_wheel_acceleration>

        <publish_odom>true</publish_odom>
        <publish_odom_tf>true</publish_odom_tf>
        <publish_wheel_tf>true</publish_wheel_tf>

        <odometry_frame>odom</odometry_frame>
        <robot_base_frame>base_link</robot_base_frame>

      </plugin>

</gazebo> -->








</robot>
