<?xml version="1.0" encoding="utf-8"?>
<!-- This URDF was automatically created by SolidWorks to URDF Exporter! Originally created by Stephen Brawner (brawner@gmail.com) 
     Commit Version: 1.6.0-1-g15f4949  Build Version: 1.6.7594.29634
     For more information, please see http://wiki.ros.org/sw_urdf_exporter -->
<robot
  name="limo_s2_description">
  <link
    name="base_link">
    <inertial>
      <origin
        xyz="0.0122854831271005 0.000301648748017558 0.00574813366704866"
        rpy="0 0 0" />
      <mass
        value="0.935880940379454" />
      <inertia
        ixx="0.00230607305054725"
        ixy="-2.1703175852137E-06"
        ixz="-0.000107737732961607"
        iyy="0.00211409736296743"
        iyz="-6.53845042786095E-07"
        izz="0.0038728434760199" />
    </inertial>
    <visual>
      <origin
        xyz="0.1 0 0"
        rpy="0 0 1.57" />
      <geometry>
        <mesh
          filename="package://limo_s2_description/meshes/dae/base_link.dae" />
      </geometry>
      <material
        name="">
        <color
          rgba="0.898039215686275 0.917647058823529 0.929411764705882 1" />
      </material>
    </visual>
    <collision>
      <origin
        xyz="0 0 0"
        rpy="0 0 0" />
      <geometry>
        <mesh
          filename="package://limo_s2_description/meshes/dae/base_link.dae" />
      </geometry>
    </collision>
  </link>
  <link
    name="front_left_wheel_Link">
    <inertial>
      <origin
        xyz="1.8652E-06 0.017054 7.5135E-07"
        rpy="0 0 0" />
      <mass
        value="0.20445" />
      <inertia
        ixx="6.6928E-05"
        ixy="5.6721E-09"
        ixz="6.8142E-10"
        iyy="0.00011034"
        iyz="3.3358E-10"
        izz="6.6926E-05" />
    </inertial>
    <visual>
      <origin
        xyz="0 0 0"
        rpy="0 0 0" />
      <geometry>
        <mesh
          filename="package://limo_s2_description/meshes/front_left_wheel_Link.STL" />
      </geometry>
      <material
        name="">
        <color
          rgba="0.75294 0.75294 0.75294 1" />
      </material>
    </visual>
    <collision>
      <origin
        xyz="0 0 0"
        rpy="0 0 0" />
      <geometry>
        <mesh
          filename="package://limo_s2_description/meshes/front_left_wheel_Link.STL" />
      </geometry>
    </collision>
  </link>
  <joint
    name="front_left_wheel_joint"
    type="continuous">
    <origin
      xyz="0.11788 0.06634 -0.0255"
      rpy="0 0 0" />
    <parent
      link="base_link" />
    <child
      link="front_left_wheel_Link" />
    <axis
      xyz="0 1 0" />
  </joint>
  <link
    name="front_right_wheel_Link">
    <inertial>
      <origin
        xyz="1.3775E-06 0.017054 -6.6041E-07"
        rpy="0 0 0" />
      <mass
        value="0.20445" />
      <inertia
        ixx="6.6928E-05"
        ixy="6.0143E-09"
        ixz="1.0384E-10"
        iyy="0.00011034"
        iyz="1.1454E-10"
        izz="6.6926E-05" />
    </inertial>
    <visual>
      <origin
        xyz="0 0 0"
        rpy="0 0 0" />
      <geometry>
        <mesh
          filename="package://limo_s2_description/meshes/front_right_wheel_Link.STL" />
      </geometry>
      <material
        name="">
        <color
          rgba="0.75294 0.75294 0.75294 1" />
      </material>
    </visual>
    <collision>
      <origin
        xyz="0 0 0"
        rpy="0 0 0" />
      <geometry>
        <mesh
          filename="package://limo_s2_description/meshes/front_right_wheel_Link.STL" />
      </geometry>
    </collision>
  </link>
  <joint
    name="front_right_wheel_joint"
    type="continuous">
    <origin
      xyz="0.11788 -0.06667 -0.0255"
      rpy="-3.1416 0 0" />
    <parent
      link="base_link" />
    <child
      link="front_right_wheel_Link" />
    <axis
      xyz="0 1 0" />
  </joint>
  <link
    name="rear_right_wheel_Link">
    <inertial>
      <origin
        xyz="-1.3772E-06 0.017054 -1.4935E-06"
        rpy="0 0 0" />
      <mass
        value="0.20445" />
      <inertia
        ixx="6.6927E-05"
        ixy="-4.9607E-09"
        ixz="1.167E-09"
        iyy="0.00011034"
        iyz="-2.7513E-09"
        izz="6.6927E-05" />
    </inertial>
    <visual>
      <origin
        xyz="0 0 0"
        rpy="0 0 0" />
      <geometry>
        <mesh
          filename="package://limo_s2_description/meshes/rear_right_wheel_Link.STL" />
      </geometry>
      <material
        name="">
        <color
          rgba="0.75294 0.75294 0.75294 1" />
      </material>
    </visual>
    <collision>
      <origin
        xyz="0 0 0"
        rpy="0 0 0" />
      <geometry>
        <mesh
          filename="package://limo_s2_description/meshes/rear_right_wheel_Link.STL" />
      </geometry>
    </collision>
  </link>
  <joint
    name="rear_right_wheel_joint"
    type="continuous">
    <origin
      xyz="-0.085123 -0.06667 -0.0255"
      rpy="3.1416 0 0" />
    <parent
      link="base_link" />
    <child
      link="rear_right_wheel_Link" />
    <axis
      xyz="0 1 0" />
  </joint>
  <link
    name="rear_letf_wheel_Link">
    <inertial>
      <origin
        xyz="1.1015E-06 0.017054 9.9372E-07"
        rpy="0 0 0" />
      <mass
        value="0.20445" />
      <inertia
        ixx="6.6926E-05"
        ixy="2.2044E-09"
        ixz="4.6491E-10"
        iyy="0.00011034"
        iyz="5.6133E-09"
        izz="6.6927E-05" />
    </inertial>
    <visual>
      <origin
        xyz="0 0 0"
        rpy="0 0 0" />
      <geometry>
        <mesh
          filename="package://limo_s2_description/meshes/rear_letf_wheel_Link.STL" />
      </geometry>
      <material
        name="">
        <color
          rgba="0.75294 0.75294 0.75294 1" />
      </material>
    </visual>
    <collision>
      <origin
        xyz="0 0 0"
        rpy="0 0 0" />
      <geometry>
        <mesh
          filename="package://limo_s2_description/meshes/rear_letf_wheel_Link.STL" />
      </geometry>
    </collision>
  </link>
  <joint
    name="rear_letf_wheel_joint"
    type="continuous">
    <origin
      xyz="-0.085123 0.06634 -0.0255"
      rpy="0 0 0" />
    <parent
      link="base_link" />
    <child
      link="rear_letf_wheel_Link" />
    <axis
      xyz="0 1 0" />
  </joint>
  <link
    name="laser_Link">
    <inertial>
      <origin
        xyz="-0.015885 0.00013253 -0.001814"
        rpy="0 0 0" />
      <mass
        value="0.023778" />
      <inertia
        ixx="5.1422E-06"
        ixy="-1.438E-08"
        ixz="-1.6035E-09"
        iyy="8.3268E-06"
        iyz="1.8496E-08"
        izz="1.2862E-05" />
    </inertial>
    <visual>
      <origin
        xyz="0 0 0"
        rpy="0 0 0" />
      <geometry>
        <mesh
          filename="package://limo_s2_description/meshes/laser_Link.STL" />
      </geometry>
      <material
        name="">
        <color
          rgba="1 1 1 1" />
      </material>
    </visual>
    <collision>
      <origin
        xyz="0 0 0"
        rpy="0 0 0" />
      <geometry>
        <mesh
          filename="package://limo_s2_description/meshes/laser_Link.STL" />
      </geometry>
    </collision>
  </link>
  <joint
    name="laser_joint"
    type="fixed">
    <origin
      xyz="0.0038772 -0.00016487 0.0644"
      rpy="0 0 0" />
    <parent
      link="base_link" />
    <child
      link="laser_Link" />
    <axis
      xyz="0 0 0" />
  </joint>
  <link
    name="camera_Link">
    <inertial>
      <origin
        xyz="0 0 0"
        rpy="0 0 0" />
      <mass
        value="0" />
      <inertia
        ixx="0"
        ixy="0"
        ixz="0"
        iyy="0"
        iyz="0"
        izz="0" />
    </inertial>
    <visual>
      <origin
        xyz="0 0 0"
        rpy="0 0 0" />
      <geometry>
        <mesh
          filename="package://limo_s2_description/meshes/camera_Link.STL" />
      </geometry>
      <material
        name="">
        <color
          rgba="1 1 1 1" />
      </material>
    </visual>
    <collision>
      <origin
        xyz="0 0 0"
        rpy="0 0 0" />
      <geometry>
        <mesh
          filename="package://limo_s2_description/meshes/camera_Link.STL" />
      </geometry>
    </collision>
  </link>
  <joint
    name="camera_joint"
    type="fixed">
    <origin
      xyz="-0.091096 -0.00016487 0.1615"
      rpy="0 0 0" />
    <parent
      link="base_link" />
    <child
      link="camera_Link" />
    <axis
      xyz="0 0 0" />
  </joint>
</robot>