<?xml version="1.0" ?>
<!-- =================================================================================== -->
<!-- |    This document was autogenerated by xacro from ranger_mini_gazebo.xacro       | -->
<!-- |    EDITING THIS FILE BY HAND IS NOT RECOMMENDED                                 | -->
<!-- =================================================================================== -->
<robot name="ranger_mini_v3">
  <link name="base_link">
    <inertial>
      <origin rpy="0 0 0" xyz="-0.0242698272228022 -0.0030308024613212 0.0544267444673498"/>
      <mass value="10"/>
      <inertia ixx="0.1354" ixy="0.0" ixz="0.0" iyy="0.2417" iyz="0.0" izz="0.3085"/>
    </inertial>
    <visual>
      <origin rpy="3.14 0 0" xyz="0 0 0.0"/>
      <geometry>
        <mesh filename="package://ranger_mini_v3/meshes/ranger_mini3.dae"/>
      </geometry>
      <material name="">
        <color rgba="0.792156862745098 0.819607843137255 0.933333333333333 1"/>
      </material>
    </visual>
    <collision>
      <origin rpy="0 0 0" xyz="0 0 -0.1"/>
      <geometry>
        <box size="0.5 0.35 0.2"/>
      </geometry>
    </collision>
  </link>
  <link name="fr_steering_wheel_link">
    <inertial>
      <origin rpy="0 0 0" xyz="1.8493E-05 1.2713E-06 0.043679"/>
      <mass value="1"/>
      <inertia ixx="0.0063625" ixy="-1.0581E-07" ixz="-4.0831E-07" iyy="0.006363" iyz="-3.4944E-08" izz="0.010465"/>
    </inertial>
    <visual>
      <origin rpy="1.57 0 3.14" xyz="-0.248 -0.113 0.155"/>
      <geometry>
        <mesh filename="package://ranger_mini_v3/meshes/ranger_mini_v3_wheel_right.dae"/>
      </geometry>
      <material name="">
        <color rgba="0.79216 0.81961 0.93333 1"/>
      </material>
    </visual>
    <collision>
      <origin rpy="0 0 0" xyz="0 0 0"/>
      <geometry>
        <!-- <mesh
          filename="package://ranger_mini_v3/meshes/ranger_mini_v3_wheel_right.dae" /> -->
        <cylinder length="0.001" radius="0.001"/>
      </geometry>
    </collision>
  </link>
  <joint name="fr_steering_joint" type="revolute">
    <origin rpy="0 0 0" xyz="0.25 -0.19 -0.1"/>
    <parent link="base_link"/>
    <child link="fr_steering_wheel_link"/>
    <axis xyz="0 0 -1"/>
    <limit effort="5" lower="-2.1" upper="2.1" velocity="6.28"/>
  </joint>
  <link name="fr_wheel_link">
    <inertial>
      <mass value="8"/>
      <origin xyz="0 0 0"/>
      <inertia ixx="0.02047" ixy="0.0" ixz="0.0" iyy="0.02047" iyz="0.0" izz="0.0324"/>
    </inertial>
    <visual>
      <origin rpy="1.57 0 0" xyz="0 0 0"/>
      <geometry>
        <cylinder length="0.01" radius="0.01"/>
      </geometry>
    </visual>
    <collision>
      <origin rpy="1.57 0 0" xyz="0 0 -0.005"/>
      <geometry>
        <cylinder length="0.08" radius="0.09"/>
      </geometry>
      <contact>
        <ode>
          <min_depth>0.001</min_depth>
        </ode>
      </contact>
    </collision>
  </link>
  <joint name="fr_wheel" type="continuous">
    <origin rpy="0 0 0" xyz="0.0 0.0 -0.12"/>
    <parent link="fr_steering_wheel_link"/>
    <child link="fr_wheel_link"/>
    <axis rpy="0 0 0" xyz="0 1 0"/>
  </joint>
  <link name="fl_steering_wheel_link">
    <inertial>
      <origin rpy="0 0 0" xyz="-0.0017956 -9.6304E-08 0.043642"/>
      <mass value="1"/>
      <inertia ixx="0.0063695" ixy="-2.1067E-08" ixz="-0.00016867" iyy="0.006363" iyz="-1.0301E-08" izz="0.010458"/>
    </inertial>
    <visual>
      <origin rpy="1.57 0.0 3.14" xyz="-0.248 -0.125 -0.192"/>
      <geometry>
        <mesh filename="package://ranger_mini_v3/meshes/ranger_mini_v3_wheel.dae"/>
      </geometry>
      <material name="">
        <color rgba="0.79216 0.81961 0.93333 1"/>
      </material>
    </visual>
    <collision>
      <origin rpy="0 0 0" xyz="0 0 0"/>
      <geometry>
        <!-- <mesh
          filename="package://ranger_mini_v3/meshes/ranger_mini_v3_wheel.dae" /> -->
        <cylinder length="0.001" radius="0.001"/>
      </geometry>
    </collision>
  </link>
  <joint name="fl_steering_joint" type="revolute">
    <origin rpy="0 0 0" xyz="0.25 0.19 -0.1"/>
    <parent link="base_link"/>
    <child link="fl_steering_wheel_link"/>
    <axis xyz="0 0 -1"/>
    <limit effort="5" lower="-2.1" upper="2.1" velocity="6.28"/>
  </joint>
  <link name="fl_wheel_link">
    <inertial>
      <mass value="8"/>
      <origin xyz="0 0 0"/>
      <inertia ixx="0.02047" ixy="0.0" ixz="0.0" iyy="0.02047" iyz="0.0" izz="0.0324"/>
    </inertial>
    <visual>
      <origin rpy="1.57 0 0" xyz="0 0 0"/>
      <geometry>
        <cylinder length="0.01" radius="0.01"/>
      </geometry>
    </visual>
    <collision>
      <origin rpy="1.57 0 0" xyz="0 0 0"/>
      <geometry>
        <cylinder length="0.08" radius="0.09"/>
      </geometry>
      <contact>
        <ode>
          <min_depth>0.001</min_depth>
        </ode>
      </contact>
    </collision>
  </link>
  <joint name="fl_wheel" type="continuous">
    <origin rpy="0 0 0" xyz="0.0 0.0 -0.12"/>
    <parent link="fl_steering_wheel_link"/>
    <child link="fl_wheel_link"/>
    <axis rpy="0 0 0" xyz="0 1 0"/>
  </joint>
  <link name="rl_steering_wheel_link">
    <inertial>
      <origin rpy="0 0 0" xyz="-0.00017093 6.1255E-08 0.043678"/>
      <mass value="1"/>
      <inertia ixx="0.0063627" ixy="-2.1069E-08" ixz="-1.587E-05" iyy="0.006363" iyz="9.3201E-09" izz="0.010465"/>
    </inertial>
    <visual>
      <origin rpy="1.57 0 3.14" xyz="-0.241 -0.11 0.155"/>
      <geometry>
        <mesh filename="package://ranger_mini_v3/meshes/ranger_mini_v3_wheel_right.dae"/>
      </geometry>
      <material name="">
        <color rgba="0.79216 0.81961 0.93333 1"/>
      </material>
    </visual>
    <collision>
      <origin rpy="0 0 0" xyz="0 0 0"/>
      <geometry>
        <!-- <mesh
          filename="package://ranger_mini_v3/meshes/ranger_mini_v3_wheel_right.dae" /> -->
        <cylinder length="0.001" radius="0.001"/>
      </geometry>
    </collision>
  </link>
  <joint name="rl_steering_joint" type="revolute">
    <origin rpy="0 0 0" xyz="-0.25 0.19 -0.1"/>
    <parent link="base_link"/>
    <child link="rl_steering_wheel_link"/>
    <axis xyz="0 0 -1"/>
    <limit effort="5" lower="-2.1" upper="2.1" velocity="6.28"/>
  </joint>
  <link name="rl_wheel_link">
    <inertial>
      <mass value="8"/>
      <origin xyz="0 0 0"/>
      <inertia ixx="0.02047" ixy="0.0" ixz="0.0" iyy="0.02047" iyz="0.0" izz="0.0324"/>
    </inertial>
    <visual>
      <origin rpy="1.57 0 0" xyz="0 0 0"/>
      <geometry>
        <cylinder length="0.01" radius="0.01"/>
      </geometry>
    </visual>
    <collision>
      <origin rpy="1.57 0 0" xyz="0.005 0.005 -0.005"/>
      <geometry>
        <cylinder length="0.08" radius="0.09"/>
      </geometry>
      <contact>
        <ode>
          <min_depth>0.001</min_depth>
        </ode>
      </contact>
    </collision>
  </link>
  <joint name="rl_wheel" type="continuous">
    <origin rpy="0 0 0" xyz="0.0 0.0 -0.12 "/>
    <parent link="rl_steering_wheel_link"/>
    <child link="rl_wheel_link"/>
    <axis rpy="0 0 0" xyz="0 1 0"/>
  </joint>
  <link name="rr_steering_wheel_link">
    <inertial>
      <origin xyz="0.0 0.0 0.0"/>
      <mass value="1"/>
      <inertia ixx="0.01" ixy="0.0" ixz="0.0" iyy="0.01" iyz="0.0" izz="0.01"/>
    </inertial>
    <visual>
      <origin rpy="1.57 0 3.14 " xyz="-0.262 -0.095 0.155"/>
      <geometry>
        <mesh filename="package://ranger_mini_v3/meshes/ranger_mini_v3_wheel_right.dae"/>
      </geometry>
    </visual>
    <collision>
      <origin rpy="0 0 0" xyz="0 0 0"/>
      <geometry>
        <cylinder length="0.001" radius="0.001"/>
      </geometry>
    </collision>
  </link>
  <joint name="rr_steering_joint" type="revolute">
    <origin rpy="0 0 0" xyz="-0.23 -0.206 -0.1"/>
    <parent link="base_link"/>
    <child link="rr_steering_wheel_link"/>
    <axis rpy="0 0 0" xyz="0 0 -1"/>
    <limit effort="5" lower="-2.1" upper="2.1" velocity="6.28"/>
  </joint>
  <link name="rr_wheel_link">
    <inertial>
      <mass value="8"/>
      <origin xyz="0 0 0"/>
      <inertia ixx="0.02047" ixy="0.0" ixz="0.0" iyy="0.02047" iyz="0.0" izz="0.0324"/>
    </inertial>
    <visual>
      <origin rpy="1.57 0 0" xyz="0.0 0.0 0.0"/>
      <geometry>
        <cylinder length="0.01" radius="0.01"/>
      </geometry>
    </visual>
    <collision>
      <origin rpy="1.57 0 0" xyz="-0.015 0.02 -0.005"/>
      <geometry>
        <cylinder length="0.08" radius="0.09"/>
      </geometry>
      <contact>
        <ode>
          <min_depth>0.001</min_depth>
        </ode>
      </contact>
    </collision>
  </link>
  <joint name="rr_wheel" type="continuous">
    <origin rpy="0 0 0" xyz="0.0 0.0 -0.12 "/>
    <parent link="rr_steering_wheel_link"/>
    <child link="rr_wheel_link"/>
    <axis rpy="0 0 0" xyz="0 1 0"/>
  </joint>
  <transmission name="fl_steering_wheel_trans">
    <type>transmission_interface/SimpleTransmission</type>
    <joint name="fl_steering_joint">
      <hardwareInterface>hardware_interface/PositionJointInterface</hardwareInterface>
    </joint>
    <actuator name="fl_steering_wheel_motor">
      <hardwareInterface>hardware_interface/PositionJointInterface</hardwareInterface>
      <mechanicalReduction>30</mechanicalReduction>
    </actuator>
  </transmission>
  <transmission name="fr_steering_wheel_trans">
    <type>transmission_interface/SimpleTransmission</type>
    <joint name="fr_steering_joint">
      <hardwareInterface>hardware_interface/PositionJointInterface</hardwareInterface>
    </joint>
    <actuator name="fr_steering_wheel_motor">
      <hardwareInterface>hardware_interface/PositionJointInterface</hardwareInterface>
      <mechanicalReduction>30</mechanicalReduction>
    </actuator>
  </transmission>
  <transmission name="rl_steering_wheel_trans">
    <type>transmission_interface/SimpleTransmission</type>
    <joint name="rl_steering_joint">
      <hardwareInterface>hardware_interface/PositionJointInterface</hardwareInterface>
    </joint>
    <actuator name="rl_steering_wheel_motor">
      <hardwareInterface>hardware_interface/PositionJointInterface</hardwareInterface>
      <mechanicalReduction>30</mechanicalReduction>
    </actuator>
  </transmission>
  <transmission name="rr_steering_wheel_trans">
    <type>transmission_interface/SimpleTransmission</type>
    <joint name="rr_steering_joint">
      <hardwareInterface>hardware_interface/PositionJointInterface</hardwareInterface>
    </joint>
    <actuator name="rr_steering_wheel_motor">
      <hardwareInterface>hardware_interface/PositionJointInterface</hardwareInterface>
      <mechanicalReduction>30</mechanicalReduction>
    </actuator>
  </transmission>
  <transmission name="fl_wheel_trans">
    <type>transmission_interface/SimpleTransmission</type>
    <joint name="fl_wheel">
      <hardwareInterface>hardware_interface/VelocityJointInterface</hardwareInterface>
    </joint>
    <actuator name="fl_wheel_motor">
      <hardwareInterface>hardware_interface/VelocityJointInterface</hardwareInterface>
      <mechanicalReduction>30</mechanicalReduction>
    </actuator>
  </transmission>
  <transmission name="fr_wheel_trans">
    <type>transmission_interface/SimpleTransmission</type>
    <joint name="fr_wheel">
      <hardwareInterface>hardware_interface/VelocityJointInterface</hardwareInterface>
    </joint>
    <actuator name="fr_wheel_motor">
      <hardwareInterface>hardware_interface/VelocityJointInterface</hardwareInterface>
      <mechanicalReduction>30</mechanicalReduction>
    </actuator>
  </transmission>
  <transmission name="rl_wheel_trans">
    <type>transmission_interface/SimpleTransmission</type>
    <joint name="rl_wheel">
      <hardwareInterface>hardware_interface/VelocityJointInterface</hardwareInterface>
    </joint>
    <actuator name="rl_wheel_motor">
      <hardwareInterface>hardware_interface/VelocityJointInterface</hardwareInterface>
      <mechanicalReduction>30</mechanicalReduction>
    </actuator>
  </transmission>
  <transmission name="rr_wheel_trans">
    <type>transmission_interface/SimpleTransmission</type>
    <joint name="rr_wheel">
      <hardwareInterface>hardware_interface/VelocityJointInterface</hardwareInterface>
    </joint>
    <actuator name="rr_wheel_motor">
      <hardwareInterface>hardware_interface/VelocityJointInterface</hardwareInterface>
      <mechanicalReduction>30</mechanicalReduction>
    </actuator>
  </transmission>
  <gazebo>
    <plugin filename="libgazebo_ros_control.so" name="gazebo_ros_control">
    </plugin>
  </gazebo>
</robot>
