<?xml version="1.0" encoding="utf-8"?>
<!-- This URDF was automatically created by SolidWorks to URDF Exporter! Originally created by Stephen Brawner (brawner@gmail.com) 
     Commit Version: 1.6.0-1-g15f4949  Build Version: 1.6.7594.29634
     For more information, please see http://wiki.ros.org/sw_urdf_exporter -->
<robot
  name="hunter_se_description">
  <link
    name="base_link">
    <inertial>
      <origin
        xyz="0.0374140021041951 -0.000373005187591258 -0.0771282894414029"
        rpy="0 0 0" />
      <mass
        value="24.73" />
      <inertia
        ixx="0.123215829336501"
        ixy="-2.51201031615063E-06"
        ixz="0.00480100638469038"
        iyy="0.219144715482931"
        iyz="-1.0329581476775E-05"
        izz="0.313606030126045" />
    </inertial>
    <visual>
      <origin
        xyz="0 0 0"
        rpy="0 0 0" />
      <geometry>
        <mesh
          filename="package://hunter_se_description/meshes/base_link.STL" />
      </geometry>
      <material
        name="">
        <color
          rgba="0.752941176470588 0.752941176470588 0.752941176470588 1" />
      </material>
    </visual>
    <collision>
      <origin
        xyz="0 0 0"
        rpy="0 0 0" />
      <geometry>
        <mesh
          filename="package://hunter_se_description/meshes/base_link.STL" />
      </geometry>
    </collision>
  </link>
  <link
    name="fr_steer_left_link">
    <inertial>
      <origin
        xyz="-0.0002776492198312 0.0163539773588368 4.97346169803237E-09"
        rpy="0 0 0" />
      <mass
        value="3.149" />
      <inertia
        ixx="0.0222"
        ixy="0.0"
        ixz="0.0"
        iyy="0.0222"
        iyz="0.0"
        izz="0.0378075" />
    </inertial>
    <visual>
      <origin
        xyz="0 0 0"
        rpy="0 0 0" />
      <geometry>
        <box size="0.001 0.001 0.001"/>
      </geometry>
      <material
        name="">
        <color
          rgba="0.223529411764706 0.223529411764706 0.223529411764706 1" />
      </material>
    </visual>
    <collision>
      <origin
        xyz="0 0 0"
        rpy="0 0 0" />
      <geometry>
        <box size="0.001 0.001 0.001"/>
      </geometry>
    </collision>
  </link>
  <joint
    name="fr_steer_left_joint"
    type="revolute">
    <origin
      xyz="0.34058 0.24619 -0.1535"
      rpy="0 0 0" />
    <parent
      link="base_link" />
    <child
      link="fr_steer_left_link" />
    <axis
      xyz="0 0 1" />
    <limit
      lower="-0.69"
      upper="0.69"
      effort="0"
      velocity="0" />
  </joint>
  <link
    name="fr_left_link">
    <inertial>
      <origin
        xyz="-3.5837499634539E-10 4.97346158701006E-09 -0.016356334080185"
        rpy="0 0 0" />
      <mass
        value="3.149" />
      <inertia
        ixx="0.0222"
        ixy="0.0"
        ixz="0.0"
        iyy="0.0222"
        iyz="0.0"
        izz="0.0378075" />
    </inertial>
    <visual>
      <origin
        xyz="0 0 0"
        rpy="0 0 0" />
      <geometry>
        <mesh
          filename="package://hunter_se_description/meshes/fr_left_link.STL" />
      </geometry>
      <material
        name="">
        <color
          rgba="0.223529411764706 0.223529411764706 0.223529411764706 1" />
      </material>
    </visual>
    <collision>
      <origin
        xyz="0 0 0"
        rpy="0 0 0" />
      <geometry>
        <mesh
          filename="package://hunter_se_description/meshes/fr_left_link.STL" />
      </geometry>
    </collision>
  </link>
  <joint
    name="fr_left_joint"
    type="continuous">
    <origin
      xyz="0 0 0"
      rpy="1.5708 0 0.016976" />
    <parent
      link="fr_steer_left_link" />
    <child
      link="fr_left_link" />
    <axis
      xyz="0 0 -1" />
     <dynamics damping="0.0" friction="15"/>      
  </joint>
  <link
    name="fr_steer_right_link">
    <inertial>
      <origin
        xyz="0.000274981985673328 -0.0163540222836661 -3.24802407192237E-11"
        rpy="0 0 0" />
      <mass
        value="3.149" />
      <inertia
        ixx="0.0222"
        ixy="0.0"
        ixz="0.0"
        iyy="0.0222"
        iyz="0.0"
        izz="0.0378075" />
    </inertial>
    <visual>
      <origin
        xyz="0 0 0"
        rpy="0 0 0" />
      <geometry>
        <box size="0.001 0.001 0.001"/>
      </geometry>
      <material
        name="">
        <color
          rgba="1 1 1 1" />
      </material>
    </visual>
    <collision>
      <origin
        xyz="0 0 0"
        rpy="0 0 0" />
      <geometry>
        <box size="0.001 0.001 0.001"/>
      </geometry>
    </collision>
  </link>
  <joint
    name="fr_steer_right_joint"
    type="revolute">
    <origin
      xyz="0.34219 -0.24619 -0.1535"
      rpy="0 0 0" />
    <parent
      link="base_link" />
    <child
      link="fr_steer_right_link" />
    <axis
      xyz="0 0 1" />
    <limit
      lower="-0.69"
      upper="0.69"
      effort="0"
      velocity="0" />
  </joint>
  <link
    name="fr_right_link">
    <inertial>
      <origin
        xyz="0.00027498198567355 3.24801296969213E-11 -0.0163540222836661"
        rpy="0 0 0" />
      <mass
        value="3.149" />
      <inertia
        ixx="0.0222"
        ixy="0.0"
        ixz="0.0"
        iyy="0.0222"
        iyz="0.0"
        izz="0.0378075" />
    </inertial>
    <visual>
      <origin
        xyz="0 0 0"
        rpy="0 0 0" />
      <geometry>
        <mesh
          filename="package://hunter_se_description/meshes/fr_right_link.STL" />
      </geometry>
      <material
        name="">
        <color
          rgba="0.223529411764706 0.223529411764706 0.223529411764706 1" />
      </material>
    </visual>
    <collision>
      <origin
        xyz="0 0 0"
        rpy="0 0 0" />
      <geometry>
        <mesh
          filename="package://hunter_se_description/meshes/fr_right_link.STL" />
      </geometry>
    </collision>
  </link>
  <joint
    name="fr_right_joint"
    type="continuous">
    <origin
      xyz="0 0 0"
      rpy="-1.5708 0 0" />
    <parent
      link="fr_steer_right_link" />
    <child
      link="fr_right_link" />
    <axis
      xyz="0 0 1" />
    <dynamics damping="0.0" friction="15"/>
  </joint>

  <link
    name="re_left_link">
    <inertial>
      <origin
        xyz="1.245E-09 1.7252E-06 -0.010284"
        rpy="0 0 0" />
      <mass
        value="3.149" />
      <inertia
        ixx="0.0222"
        ixy="0.0"
        ixz="0.0"
        iyy="0.0222"
        iyz="0.0"
        izz="0.0378075" />
    </inertial>
    <visual>
      <origin
        xyz="0 0 0"
        rpy="0 0 0" />
      <geometry>
        <mesh
          filename="package://hunter_se_description/meshes/re_left_link.STL" />
      </geometry>
      <material
        name="">
        <color
          rgba="0.37647 0.37647 0.37647 1" />
      </material>
    </visual>
    <collision>
      <origin
        xyz="0 0 0"
        rpy="0 0 0" />
      <geometry>
        <mesh
          filename="package://hunter_se_description/meshes/re_left_link.STL" />
      </geometry>
    </collision>
  </link>
  <joint
    name="re_left_joint"
    type="continuous">
    <origin
      xyz="-0.2078 0.252 -0.158"
      rpy="1.5708 0 0" />
    <parent
      link="base_link" />
    <child
      link="re_left_link" />
    <axis
      xyz="0 0 -1" />
    <dynamics damping="0.0" friction="15"/>
  </joint>
  <link
    name="re_right_link">
    <inertial>
      <origin
        xyz="0 0 0"
        rpy="0 0 0" />
      <mass
        value="3.149" />
      <inertia
        ixx="0.0222"
        ixy="0.0"
        ixz="0.0"
        iyy="0.0222"
        iyz="0.0"
        izz="0.0378075" />
    </inertial>
    <visual>
      <origin
        xyz="0 0 0"
        rpy="0 0 0" />
      <geometry>
        <mesh
          filename="package://hunter_se_description/meshes/re_right_link.STL" />
      </geometry>
      <material
        name="">
        <color
          rgba="1 1 1 1" />
      </material>
    </visual>
    <collision>
      <origin
        xyz="0 0 0"
        rpy="0 0 0" />
      <geometry>
        <mesh
          filename="package://hunter_se_description/meshes/re_right_link.STL" />
      </geometry>
    </collision>
  </link>
  <joint
    name="re_right_joint"
    type="continuous">
    <origin
      xyz="-0.2078 -0.252 -0.158"
      rpy="-1.5708 0 0" />
    <parent
      link="base_link" />
    <child
      link="re_right_link" />
    <axis
      xyz="0 0 1" />
    <dynamics damping="0.0" friction="15"/>
  </joint>

  <link
    name="front_steer_link">
    <inertial>
      <origin
        xyz="0.049836 8.1046E-15 0.017912"
        rpy="0 0 0" />
      <mass
        value="0.0049179" />
      <inertia
        ixx="1.6846E-07"
        ixy="7.6396E-23"
        ixz="-1.0974E-08"
        iyy="7.549E-07"
        iyz="-1.8957E-22"
        izz="7.334E-07" />
    </inertial>
    <visual>
      <origin
        xyz="0 0 0"
        rpy="0 0 0" />
      <geometry>
      <cylinder length="0.001" radius="0.005"/>
      </geometry>
      <material
        name="">
        <color
          rgba="0.79216 0.81961 0.93333 1" />
      </material>
    </visual>
    <collision>
      <origin
        xyz="0 0 0"
        rpy="0 0 0" />
      <geometry>
      <cylinder length="0.001" radius="0.005"/>
      </geometry>
    </collision>
  </link>
  <joint
    name="front_steer_joint"
    type="revolute">
    <origin
      xyz="0.40792 -1.1431E-05 -0.085581"
      rpy="0 0 0" />
    <parent
      link="base_link" />
    <child
      link="front_steer_link" />
    <axis
      xyz="0 0 1" />
    <limit
      lower="-0.72"
      upper="0.72"
      effort="0"
      velocity="0" />
  </joint>
  <link
    name="rear_wheel_link">
    <inertial>
      <origin
        xyz="-0.02 0.0031269 -0.12735"
        rpy="0 0 0" />
      <mass
        value="0.0049179" />
      <inertia
        ixx="1.1821E-06"
        ixy="9.6965E-13"
        ixz="-3.1553E-12"
        iyy="9.5276E-07"
        iyz="1.2428E-08"
        izz="1.0913E-06" />
    </inertial>
    <visual>
      <origin
        xyz="0 0 0"
        rpy="0 0 0" />
      <geometry>
      <cylinder length="0.001" radius="0.005"/>
      </geometry>
      <material
        name="">
        <color
          rgba="1 1 1 1" />
      </material>
    </visual>
    <collision>
      <origin
        xyz="0 0 0"
        rpy="0 0 0" />
      <geometry>
      <cylinder length="0.001" radius="0.005"/>
      </geometry>
    </collision>
  </link>
  <joint
    name="rear_wheel_joint"
    type="continuous">
    <origin
      xyz="-0.30408 -1.1431E-05 -0.085581"
      rpy="0.0032313 0 0" />
    <parent
      link="base_link" />
    <child
      link="rear_wheel_link" />
    <axis
      xyz="0 0 1" />
  </joint>
  
  
  
    <gazebo reference="fr_left_link"> 
    <mu1>0.8</mu1>
    <mu2>0.8</mu2>
    <kp>500000.0</kp>
    <kd>10.0</kd>
    <minDepth>0.001</minDepth>
    <maxVel>0.1</maxVel>
    <fdir1>1 0 0</fdir1>
      <material>Gazebo/Grey </material>
      </gazebo>
  <gazebo reference="fr_right_link"> 
      <mu1>0.8</mu1>
    <mu2>0.8</mu2>
    <kp>500000.0</kp>
    <kd>10.0</kd>
    <minDepth>0.001</minDepth>
    <maxVel>0.1</maxVel>
    <fdir1>1 0 0</fdir1>
      <material>Gazebo/Grey </material>
      </gazebo>
  <gazebo reference="re_left_link"> 
      <mu1>0.8</mu1>
    <mu2>10</mu2>
    <kp>500000.0</kp>
    <kd>10.0</kd>
    <minDepth>0.001</minDepth>
    <maxVel>0.1</maxVel>
    <fdir1>1 0 0</fdir1>
      <material>Gazebo/Grey </material>
      </gazebo>
  <gazebo reference="re_right_link"> 
      <mu1>0.8</mu1>
    <mu2>10</mu2>
    <kp>500000.0</kp>
    <kd>10.0</kd>
    <minDepth>0.001</minDepth>
    <maxVel>0.1</maxVel>
    <fdir1>1 0 0</fdir1>
      <material>Gazebo/Grey </material>
      </gazebo>

  <gazebo>
    <plugin name="gazebo_ros_control" filename="libgazebo_ros_control.so">
      <robotSimType>steer_bot_hardware_gazebo/SteerBotHardwareGazebo</robotSimType>
      <legacyModeNS>false</legacyModeNS>
    </plugin>
  </gazebo>



</robot>
