<?xml version="1.0" encoding="utf-8"?>
<!-- This URDF was automatically created by SolidWorks to URDF Exporter! Originally created by Stephen Brawner (brawner@gmail.com) 
     Commit Version: 1.6.0-1-g15f4949  Build Version: 1.6.7594.29634
     For more information, please see http://wiki.ros.org/sw_urdf_exporter -->
<robot
  name="hunter2_base">
  <link name="base_link">
    <inertial>
      <origin
        xyz="-0.0004092 0.026699 -0.1359"
        rpy="0 0 0" />
      <mass
        value="6.0295" />
      <inertia
        ixx="0.11107"
        ixy="1.0132E-06"
        ixz="5.1331E-07"
        iyy="0.033237"
        iyz="-0.0018886"
        izz="0.12661" />
    </inertial>
    <visual>
      <origin
        xyz="0 0 0"
        rpy="0 0 0" />
      <geometry>
        <mesh
          filename="package://hunter2_base/meshes/base_link.STL" />
      </geometry>
      <material
        name="">
        <color
          rgba="0.79216 0.81961 0.93333 1" />
      </material>
    </visual>
    <collision>
      <origin
        xyz="0 0 0"
        rpy="0 0 0" />
      <geometry>
        <mesh
          filename="package://hunter2_base/meshes/base_link.STL" />
      </geometry>
    </collision>
  </link>

  <link
    name="front_steer_left_link">
    <inertial>
      <origin
        xyz="0.0023132 0.012614 -1.8116E-05"
        rpy="0 0 0" />
      <mass
        value="0.2526" />
      <inertia
        ixx="0.11091"
        ixy="-3.1921E-07"
        ixz="-2.9854E-08"
        iyy="0.063827"
        iyz="1.5154E-07"
        izz="0.063827" />
    </inertial>
    <visual>
      <origin
        xyz="0 0 0"
        rpy="0 0 0" />
      <geometry>
       <cylinder length="0.001" radius="0.005"/>
      </geometry>
      <material
        name="">
        <color
          rgba="0.79216 0.81961 0.93333 1" />
      </material>
    </visual>
    <collision>
      <origin
        xyz="0 0 0"
        rpy="0 0 0" />
      <geometry>
       <cylinder length="0.001" radius="0.005"/>
      </geometry>
    </collision>
  </link>
  <joint
    name="front_steer_left_joint"
    type="revolute">
    <origin
      xyz="-0.29199 0.37142 -0.1955"
      rpy="3.1416 0 0" />
    <parent
      link="base_link" />
    <child
      link="front_steer_left_link" />
    <axis
      xyz="0 0 1" />
    <limit
      lower="-0.69"
      upper="0.69"
      effort="0"
      velocity="0" />
  </joint>

  <link
    name="front_left_wheel_link">
    <inertial>
      <origin
        xyz="-0.0096386 6.5774E-06 -2.0242E-05"
        rpy="0 0 0" />
      <mass
        value="7.7007" />
      <inertia
        ixx="0.11072"
        ixy="-2.2753E-07"
        ixz="4.88E-08"
        iyy="0.063724"
        iyz="-3.8745E-08"
        izz="0.063724" />
    </inertial>
    <visual>
      <origin
        xyz="0 0 0"
        rpy="0 0 0" />
      <geometry>
        <mesh
          filename="package://hunter2_base/meshes/front_left_wheel_link.STL" />
      </geometry>
      <material
        name="">
        <color
          rgba="0.79216 0.81961 0.93333 1" />
      </material>
    </visual>
    <collision>
      <origin
        xyz="0 0 0"
        rpy="0 0 0" />
      <geometry>
        <mesh
          filename="package://hunter2_base/meshes/front_left_wheel_link.STL" />
      </geometry>
    </collision>
  </link>
  <joint
    name="front_left_wheel_joint"
    type="continuous">
    <origin
      xyz="0 0 0"
      rpy="0 0 0" />
    <parent
      link="front_steer_left_link" />
    <child
      link="front_left_wheel_link" />
    <axis
      xyz="-1 0 0" />
  </joint>
  
  <link
    name="front_steer_right_link">
    <inertial>
      <origin
        xyz="0.0095958 8.9374E-08 -1.0997E-07"
        rpy="0 0 0" />
      <mass
        value="0.2526" />
      <inertia
        ixx="0.11068"
        ixy="2.0159E-08"
        ixz="-6.4721E-08"
        iyy="0.063704"
        iyz="-6.3892E-08"
        izz="0.063704" />
    </inertial>
    <visual>
      <origin
        xyz="0 0 0"
        rpy="0 0 0" />
      <geometry>
       <cylinder length="0.001" radius="0.005"/>
      </geometry>
      <material
        name="">
        <color
          rgba="0.79216 0.81961 0.93333 1" />
      </material>
    </visual>
    <collision>
      <origin
        xyz="0 0 0"
        rpy="0 0 0" />
      <geometry>
       <cylinder length="0.001" radius="0.005"/>
      </geometry>
    </collision>
  </link>
  <joint
    name="front_steer_right_joint"
    type="revolute">
    <origin
      xyz="0.29201 0.37142 -0.1955"
      rpy="3.1416 0 0" />
    <parent
      link="base_link" />
    <child
      link="front_steer_right_link" />
    <axis
      xyz="0 0 1" />
    <limit
      lower="-0.69"
      upper="0.69"
      effort="0"
      velocity="0" />
  </joint>

  <link
    name="front_right_wheel_link">
    <inertial>
      <origin
        xyz="0.0095049 9.1148E-08 -1.1284E-07"
        rpy="0 0 0" />
      <mass
        value="7.5613" />
      <inertia
        ixx="0.11054"
        ixy="2.0164E-08"
        ixz="-6.4721E-08"
        iyy="0.063626"
        iyz="-6.4092E-08"
        izz="0.063626" />
    </inertial>
    <visual>
      <origin
        xyz="0 0 0"
        rpy="0 0 0" />
      <geometry>
        <mesh
          filename="package://hunter2_base/meshes/front_right_wheel_link.STL" />
      </geometry>
      <material
        name="">
        <color
          rgba="0.79216 0.81961 0.93333 1" />
      </material>
    </visual>
    <collision>
      <origin
        xyz="0 0 0"
        rpy="0 0 0" />
      <geometry>
        <mesh
          filename="package://hunter2_base/meshes/front_right_wheel_link.STL" />
      </geometry>
    </collision>
  </link>
  <joint
    name="front_right_wheel_joint"
    type="continuous">
    <origin
      xyz="0 0 0"
      rpy="0 0 0" />
    <parent
      link="front_steer_right_link" />
    <child
      link="front_right_wheel_link" />
    <axis
      xyz="-1 0 0" />
  </joint>
  <link
    name="left_rear_link">
    <inertial>
      <origin
        xyz="-0.0096491 8.826E-05 -6.4342E-05"
        rpy="0 0 0" />
      <mass
        value="7.6692" />
      <inertia
        ixx="0.11067"
        ixy="-2.638E-08"
        ixz="5.9934E-08"
        iyy="0.063699"
        iyz="-2.542E-07"
        izz="0.063699" />
    </inertial>
    <visual>
      <origin
        xyz="0 0 0"
        rpy="0 0 0" />
      <geometry>
        <mesh
          filename="package://hunter2_base/meshes/left_rear_link.STL" />
      </geometry>
      <material
        name="">
        <color
          rgba="0.79216 0.81961 0.93333 1" />
      </material>
    </visual>
    <collision>
      <origin
        xyz="0 0 0"
        rpy="0 0 0" />
      <geometry>
        <mesh
          filename="package://hunter2_base/meshes/left_rear_link.STL" />
      </geometry>
    </collision>
  </link>
  <joint
    name="left_rear_joint"
    type="continuous">
    <origin
      xyz="-0.29249 -0.28 -0.19558"
      rpy="3.1416 0 0" />
    <parent
      link="base_link" />
    <child
      link="left_rear_link" />
    <axis
      xyz="-1 0 0" />
    <limit
      effort="100"
      velocity="1" />
  </joint>
  <link
    name="right_rear_link">
    <inertial>
      <origin
        xyz="0.0097824 -8.6542E-05 -7.4259E-05"
        rpy="0 0 0" />
      <mass
        value="7.7133" />
      <inertia
        ixx="0.11073"
        ixy="-2.6538E-08"
        ixz="-5.987E-08"
        iyy="0.06373"
        iyz="2.5385E-07"
        izz="0.06373" />
    </inertial>
    <visual>
      <origin
        xyz="0 0 0"
        rpy="0 0 0" />
      <geometry>
        <mesh
          filename="package://hunter2_base/meshes/right_rear_link.STL" />
      </geometry>
      <material
        name="">
        <color
          rgba="0.79216 0.81961 0.93333 1" />
      </material>
    </visual>
    <collision>
      <origin
        xyz="0 0 0"
        rpy="0 0 0" />
      <geometry>
        <mesh
          filename="package://hunter2_base/meshes/right_rear_link.STL" />
      </geometry>
    </collision>
  </link>
  <joint
    name="right_rear_joint"
    type="continuous">
    <origin
      xyz="0.29251 -0.28018 -0.19558"
      rpy="3.1416 0 0" />
    <parent
      link="base_link" />
    <child
      link="right_rear_link" />
    <axis
      xyz="-1 0 0" />
    <limit
      effort="100"
      velocity="1" />
  </joint>
  <link
    name="front_steer_link">
    <inertial>
      <origin
        xyz="-8.1046E-15 0.049836 0.017912"
        rpy="0 0 0" />
      <mass
        value="0.0049179" />
      <inertia
        ixx="7.549E-07"
        ixy="4.1693E-23"
        ixz="1.9576E-22"
        iyy="1.6846E-07"
        iyz="-1.0974E-08"
        izz="7.334E-07" />
    </inertial>
    <visual>
      <origin
        xyz="0 0 0"
        rpy="0 0 0" />
      <geometry>
        <mesh
          filename="package://hunter2_base/meshes/front_steer_link.STL" />
      </geometry>
      <material
        name="">
        <color
          rgba="0.79216 0.81961 0.93333 1" />
      </material>
    </visual>
    <collision>
      <origin
        xyz="0 0 0"
        rpy="0 0 0" />
      <geometry>
        <mesh
          filename="package://hunter2_base/meshes/front_steer_link.STL" />
      </geometry>
    </collision>
  </link>
  <joint
    name="front_steer_joint"
    type="revolute">
    <origin
      xyz="1.1431E-05 0.44792 -0.121"
      rpy="0 0 0" />
    <parent
      link="base_link" />
    <child
      link="front_steer_link" />
    <axis
      xyz="0 0 1" />
    <limit
      lower="-0.72"
      upper="0.72"
      effort="0"
      velocity="0" />
  </joint>
  <link
    name="rear_wheel_link">
    <inertial>
      <origin
        xyz="-0.02 0.0031269 -0.12735"
        rpy="0 0 0" />
      <mass
        value="0.010062" />
      <inertia
        ixx="1.1821E-06"
        ixy="9.6965E-13"
        ixz="-3.1553E-12"
        iyy="9.5276E-07"
        iyz="1.2428E-08"
        izz="1.0913E-06" />
    </inertial>
    <visual>
      <origin
        xyz="0 0 0"
        rpy="0 0 0" />
      <geometry>
        <mesh
          filename="package://hunter2_base/meshes/rear_wheel_link.STL" />
      </geometry>
      <material
        name="">
        <color
          rgba="0.79216 0.81961 0.93333 1" />
      </material>
    </visual>
    <collision>
      <origin
        xyz="0 0 0"
        rpy="0 0 0" />
      <geometry>
        <mesh
          filename="package://hunter2_base/meshes/rear_wheel_link.STL" />
      </geometry>
    </collision>
  </link>
  <joint
    name="rear_wheel_joint"
    type="revolute">
    <origin
      xyz="1.1431E-05 -0.42408 -0.085581"
      rpy="0 0 0" />
    <parent
      link="base_link" />
    <child
      link="rear_wheel_link" />
    <axis
      xyz="0 0 1" />
    <limit
      lower="-0.72"
      upper="0.72"
      effort="0"
      velocity="0" />
  </joint>

  <gazebo>
    <plugin name="gazebo_ros_control" filename="libgazebo_ros_control.so">
      <robotNamespace>/</robotNamespace>
      <robotSimType>steer_bot_hardware_gazebo/SteerBotHardwareGazebo</robotSimType>
      <legacyModeNS>false</legacyModeNS>
    </plugin>
  </gazebo>



</robot>