<?xml version="1.0" encoding="utf-8"?>
<!-- This URDF was automatically created by SolidWorks to URDF Exporter! Originally created by Stephen Brawner (brawner@gmail.com) 
     Commit Version: 1.6.0-4-g7f85cfe  Build Version: 1.6.7995.38578
     For more information, please see http://wiki.ros.org/sw_urdf_exporter -->
<robot
  name="tracer_mini">
  <link
    name="base_link">
    <inertial>
      <origin
        xyz="0.0159871268556407 1.58872275333177E-05 -0.0309422377248268"
        rpy="0 0 0" />
      <mass
        value="24.3948952632956" />
      <inertia
        ixx="0.330322675681357"
        ixy="-8.93178579768822E-06"
        ixz="0.010552102579657"
        iyy="0.327495768676369"
        iyz="1.4143030767649E-06"
        izz="0.614434971559817" />
    </inertial>
    <visual>
      <origin
        xyz="0 0 0"
        rpy="0 0 0" />
      <geometry>
        <mesh
          filename="package://tracer_mini/meshes/base_link.STL" />
      </geometry>
      <material
        name="">
        <color
          rgba="1 1 1 1" />
      </material>
    </visual>
    <collision>
      <origin
        xyz="0 0 0"
        rpy="0 0 0" />
      <geometry>
        <mesh
          filename="package://tracer_mini/meshes/base_link.STL" />
      </geometry>
    </collision>
  </link>
  <link
    name="fl_Link">
    <inertial>
      <origin
        xyz="-0.11068 0.066655 0.10537"
        rpy="0 0 0" />
      <mass
        value="17.416" />
      <inertia
        ixx="0.24331"
        ixy="0.010574"
        ixz="8.9424E-06"
        iyy="0.43808"
        iyz="-1.4143E-06"
        izz="0.2374" />
    </inertial>
    <visual>
      <origin
        xyz="0 0 0"
        rpy="0 0 0" />
      <geometry>
        <mesh
          filename="package://tracer_mini/meshes/fl_Link.STL" />
      </geometry>
      <material
        name="">
        <color
          rgba="1 1 1 1" />
      </material>
    </visual>
    <collision>
      <origin
        xyz="0 0 0"
        rpy="0 0 0" />
      <geometry>
        <mesh
          filename="package://tracer_mini/meshes/fl_Link.STL" />
      </geometry>
    </collision>
  </link>
  <joint
    name="fl_joint"
    type="continuous">
    <origin
      xyz="0.12914 0.1054 -0.1275"
      rpy="1.5708 0 0" />
    <parent
      link="base_link" />
    <child
      link="fl_Link" />
    <axis
      xyz="0 0 1" />
  </joint>
  <link
    name="fr_Link">
    <inertial>
      <origin
        xyz="-0.11068 0.066655 -0.10543"
        rpy="0 0 0" />
      <mass
        value="17.416" />
      <inertia
        ixx="0.24331"
        ixy="0.010574"
        ixz="8.9424E-06"
        iyy="0.43808"
        iyz="-1.4143E-06"
        izz="0.2374" />
    </inertial>
    <visual>
      <origin
        xyz="0 0 0"
        rpy="0 0 0" />
      <geometry>
        <mesh
          filename="package://tracer_mini/meshes/fr_Link.STL" />
      </geometry>
      <material
        name="">
        <color
          rgba="1 1 1 1" />
      </material>
    </visual>
    <collision>
      <origin
        xyz="0 0 0"
        rpy="0 0 0" />
      <geometry>
        <mesh
          filename="package://tracer_mini/meshes/fr_Link.STL" />
      </geometry>
    </collision>
  </link>
  <joint
    name="fr_joint"
    type="continuous">
    <origin
      xyz="0.12914 -0.1054 -0.1275"
      rpy="1.5708 0 0" />
    <parent
      link="base_link" />
    <child
      link="fr_Link" />
    <axis
      xyz="0 0 -1" />
  </joint>
  <link
    name="rr_Link">
    <inertial>
      <origin
        xyz="0.14232 0.089655 -0.12503"
        rpy="0 0 0" />
      <mass
        value="17.416" />
      <inertia
        ixx="0.24331"
        ixy="0.010574"
        ixz="8.9424E-06"
        iyy="0.43808"
        iyz="-1.4143E-06"
        izz="0.2374" />
    </inertial>
    <visual>
      <origin
        xyz="0 0 0"
        rpy="0 0 0" />
      <geometry>
        <mesh
          filename="package://tracer_mini/meshes/rr_Link.STL" />
      </geometry>
      <material
        name="">
        <color
          rgba="1 1 1 1" />
      </material>
    </visual>
    <collision>
      <origin
        xyz="0 0 0"
        rpy="0 0 0" />
      <geometry>
        <mesh
          filename="package://tracer_mini/meshes/rr_Link.STL" />
      </geometry>
    </collision>
  </link>
  <joint
    name="rr_joint"
    type="continuous">
    <origin
      xyz="-0.12386 -0.125 -0.1505"
      rpy="1.5708 0 0" />
    <parent
      link="base_link" />
    <child
      link="rr_Link" />
    <axis
      xyz="0 0 1" />
  </joint>
  <link
    name="rl_Link">
    <inertial>
      <origin
        xyz="0.14232 0.089655 0.12497"
        rpy="0 0 0" />
      <mass
        value="17.416" />
      <inertia
        ixx="0.24331"
        ixy="0.010574"
        ixz="8.9424E-06"
        iyy="0.43808"
        iyz="-1.4143E-06"
        izz="0.2374" />
    </inertial>
    <visual>
      <origin
        xyz="0 0 0"
        rpy="0 0 0" />
      <geometry>
        <mesh
          filename="package://tracer_mini/meshes/rl_Link.STL" />
      </geometry>
      <material
        name="">
        <color
          rgba="1 1 1 1" />
      </material>
    </visual>
    <collision>
      <origin
        xyz="0 0 0"
        rpy="0 0 0" />
      <geometry>
        <mesh
          filename="package://tracer_mini/meshes/rl_Link.STL" />
      </geometry>
    </collision>
  </link>
  <joint
    name="rl_joint"
    type="continuous">
    <origin
      xyz="-0.12386 0.125 -0.1505"
      rpy="1.5708 0 0" />
    <parent
      link="base_link" />
    <child
      link="rl_Link" />
    <axis
      xyz="0 0 1" />
  </joint>
  <link
    name="laser_Link">
    <inertial>
      <origin
        xyz="0.15388 0.025965 -0.00099778"
        rpy="0 0 0" />
      <mass
        value="8.4173" />
      <inertia
        ixx="0.64711"
        ixy="0.071694"
        ixz="1.2977E-08"
        iyy="0.25316"
        iyz="1.0551E-09"
        izz="0.89983" />
    </inertial>
    <visual>
      <origin
        xyz="0 0 0"
        rpy="0 0 0" />
      <geometry>
        <mesh
          filename="package://tracer_mini/meshes/laser_Link.STL" />
      </geometry>
      <material
        name="">
        <color
          rgba="1 0.6 0 1" />
      </material>
    </visual>
    <collision>
      <origin
        xyz="0 0 0"
        rpy="0 0 0" />
      <geometry>
        <mesh
          filename="package://tracer_mini/meshes/laser_Link.STL" />
      </geometry>
    </collision>
  </link>
  <joint
    name="laser_joint"
    type="fixed">
    <origin
      xyz="0.11454 0.0015587 0.015681"
      rpy="0 0 0" />
    <parent
      link="base_link" />
    <child
      link="laser_Link" />
    <axis
      xyz="0 0 0" />
  </joint>
  <link
    name="camera_Link">
    <inertial>
      <origin
        xyz="-0.01921 0.00063228 -0.00029809"
        rpy="0 0 0" />
      <mass
        value="0.18466" />
      <inertia
        ixx="0.00039611"
        ixy="4.5151E-08"
        ixz="-7.4095E-08"
        iyy="3.5713E-05"
        iyz="1.8221E-09"
        izz="0.00040522" />
    </inertial>
    <visual>
      <origin
        xyz="0 0 0"
        rpy="0 0 0" />
      <geometry>
        <mesh
          filename="package://tracer_mini/meshes/camera_Link.STL" />
      </geometry>
      <material
        name="">
        <color
          rgba="0.79216 0.81961 0.93333 1" />
      </material>
    </visual>
    <collision>
      <origin
        xyz="0 0 0"
        rpy="0 0 0" />
      <geometry>
        <mesh
          filename="package://tracer_mini/meshes/camera_Link.STL" />
      </geometry>
    </collision>
  </link>
  <joint
    name="camera_joint"
    type="fixed">
    <origin
      xyz="0.21144 -0.00064499 0.043"
      rpy="0 0 0" />
    <parent
      link="base_link" />
    <child
      link="camera_Link" />
    <axis
      xyz="0 0 0" />
  </joint>
</robot>