<?xml version="1.0" encoding="utf-8"?>
<!-- This URDF was automatically created by SolidWorks to URDF Exporter! Originally created by Stephen Brawner (brawner@gmail.com) 
     Commit Version: 1.6.0-1-g15f4949  Build Version: 1.6.7594.29634
     For more information, please see http://wiki.ros.org/sw_urdf_exporter -->
<robot
  name="limo_s2_arm">
  <link
    name="arm_base">
    <inertial>
      <origin
        xyz="-0.0062468 -7.8708E-06 0.013495"
        rpy="0 0 0" />
      <mass
        value="0.040342" />
      <inertia
        ixx="8.5565E-06"
        ixy="-1.1664E-09"
        ixz="2.5879E-07"
        iyy="7.366E-06"
        iyz="1.3719E-09"
        izz="1.2778E-05" />
    </inertial>
    <visual>
      <origin
        xyz="0 0 0"
        rpy="0 0 0" />
      <geometry>
        <mesh
          filename="package://limo_s2_arm/meshes/arm_base.STL" />
      </geometry>
      <material
        name="">
        <color
          rgba="0.70588 0.70588 0.70588 1" />
      </material>
    </visual>
    <collision>
      <origin
        xyz="0 0 0"
        rpy="0 0 0" />
      <geometry>
        <mesh
          filename="package://limo_s2_arm/meshes/arm_base.STL" />
      </geometry>
    </collision>
  </link>
  <link
    name="arm_link1">
    <inertial>
      <origin
        xyz="0.029004 0.0033255 -0.001"
        rpy="0 0 0" />
      <mass
        value="0.006749" />
      <inertia
        ixx="2.7901E-07"
        ixy="-3.6735E-07"
        ixz="5.1618E-22"
        iyy="2.2976E-06"
        iyz="-2.8565E-23"
        izz="2.5755E-06" />
    </inertial>
    <visual>
      <origin
        xyz="0 0 0"
        rpy="0 0 0" />
      <geometry>
        <mesh
          filename="package://limo_s2_arm/meshes/arm_link1.STL" />
      </geometry>
      <material
        name="">
        <color
          rgba="0.89804 0.91765 0.92941 1" />
      </material>
    </visual>
    <collision>
      <origin
        xyz="0 0 0"
        rpy="0 0 0" />
      <geometry>
        <mesh
          filename="package://limo_s2_arm/meshes/arm_link1.STL" />
      </geometry>
    </collision>
  </link>
  <joint
    name="arm_joint1"
    type="revolute">
    <origin
      xyz="0.0024598 0 0.010616"
      rpy="1.5708 -1.5708 0" />
    <parent
      link="arm_base" />
    <child
      link="arm_link1" />
    <axis
      xyz="0 0 1" />
    <limit
      lower="-3.14"
      upper="3.14"
      effort="1"
      velocity="100" />
  </joint>
  <link
    name="arm_link2">
    <inertial>
      <origin
        xyz="0.017496 0.0069124 -0.00013621"
        rpy="0 0 0" />
      <mass
        value="0.047632" />
      <inertia
        ixx="1.0953E-05"
        ixy="-1.692E-06"
        ixz="8.1762E-08"
        iyy="2.2483E-05"
        iyz="2.5084E-08"
        izz="1.5744E-05" />
    </inertial>
    <visual>
      <origin
        xyz="0 0 0"
        rpy="0 0 0" />
      <geometry>
        <mesh
          filename="package://limo_s2_arm/meshes/arm_link2.STL" />
      </geometry>
      <material
        name="">
        <color
          rgba="0.70588 0.70588 0.70588 1" />
      </material>
    </visual>
    <collision>
      <origin
        xyz="0 0 0"
        rpy="0 0 0" />
      <geometry>
        <mesh
          filename="package://limo_s2_arm/meshes/arm_link2.STL" />
      </geometry>
    </collision>
  </link>
  <joint
    name="arm_joint2"
    type="revolute">
    <origin
      xyz="0.049139 0.0073031 0"
      rpy="0 0 -1.5708" />
    <parent
      link="arm_link1" />
    <child
      link="arm_link2" />
    <axis
      xyz="0 0 1" />
    <limit
      lower="-3.14"
      upper="3.14"
      effort="1"
      velocity="100" />
  </joint>
  <link
    name="arm_link3">
    <inertial>
      <origin
        xyz="0.01018 0.0086737 -0.0039578"
        rpy="0 0 0" />
      <mass
        value="0.03827" />
      <inertia
        ixx="3.1125E-06"
        ixy="2.3277E-16"
        ixz="-7.8003E-09"
        iyy="4.825E-06"
        iyz="7.4118E-22"
        izz="6.6134E-06" />
    </inertial>
    <visual>
      <origin
        xyz="0 0 0"
        rpy="0 0 0" />
      <geometry>
        <mesh
          filename="package://limo_s2_arm/meshes/arm_link3.STL" />
      </geometry>
      <material
        name="">
        <color
          rgba="1 1 1 1" />
      </material>
    </visual>
    <collision>
      <origin
        xyz="0 0 0"
        rpy="0 0 0" />
      <geometry>
        <mesh
          filename="package://limo_s2_arm/meshes/arm_link3.STL" />
      </geometry>
    </collision>
  </link>
  <joint
    name="arm_joint3"
    type="fixed">
    <origin
      xyz="0.065886 0.024485 0.0115"
      rpy="-1.5708 0 0" />
    <parent
      link="arm_link2" />
    <child
      link="arm_link3" />
    <axis
      xyz="0 0 0" />
  </joint>

        <transmission name="arm_joint2_trans" type="SimpleTransmission">
            <type>transmission_interface/SimpleTransmission</type>
            <actuator name="arm_joint2_motor">
                <hardwareInterface>hardware_interface/PositionJointInterface</hardwareInterface>
                <mechanicalReduction>1</mechanicalReduction>
            </actuator>
            <joint name="arm_joint2">
                <hardwareInterface>hardware_interface/PositionJointInterface</hardwareInterface>
            </joint>
        </transmission>

        <transmission name="arm_joint1_trans" type="SimpleTransmission">
            <type>transmission_interface/SimpleTransmission</type>
            <actuator name="arm_joint1_motor">
                <hardwareInterface>hardware_interface/PositionJointInterface</hardwareInterface>
                <mechanicalReduction>1</mechanicalReduction>
            </actuator>
            <joint name="arm_joint1">
                <hardwareInterface>hardware_interface/PositionJointInterface</hardwareInterface>
            </joint>
        </transmission>


</robot>