<?xml version="1.0"?>
<robot xmlns:xacro="http://ros.org/wiki/xacro" name="tracer_wheel">
    <xacro:include filename="$(find tracer_description)/urdf/rl_castor.xacro" />
    <xacro:macro name="rl_wheel" params="wheel_prefix *joint_pose">
        <link name="${wheel_prefix}_wheel_link">
            <inertial>
                <mass value="1" />
                <origin xyz="0 0 0" />
                <inertia ixx="0.3131" ixy="0" ixz="0" iyy="0.3131" iyz="0" izz="0.1361" />
                <!--<inertia ixx="0" ixy="0" ixz="0" iyy="0" iyz="0" izz="0" />-->
            </inertial>
            <visual>
                   <geometry>
                        <!--<cylinder length="0.04653" radius="0.036"/>-->
                        <!--<sphere radius="0.0457774"/>-->
                        <mesh filename="package://tracer_description/meshes/castor.dae" />
                   </geometry>
                   <!--<material name="black">
                        <color rgba="255 255 255 1"/>
                   </material>-->
            </visual>
            <collision>
              <origin
                xyz="0 0 0"
                rpy="0 0 0" />
              <geometry>
                <!--<cylinder length="0.04653" radius="0.036"/>-->
                <!--<cylinder length="0.0787019" radius="0.0457774"/>-->
                <!--<sphere radius="0.0457774"/>-->
                <mesh filename="package://tracer_description/meshes/castor.dae" />
              </geometry>
            </collision>
        </link>

        <joint name="${wheel_prefix}_wheel" type="continuous">
            <!--<origin
                  xyz="0.14547 0.20835 -0.07424"
                  rpy="0 1.57 0" />-->
            <parent link="rl_castor_link"/>
            <child link="${wheel_prefix}_wheel_link"/>
            <dynamics damping="0.0" friction="0.0"/>
            <xacro:insert_block name="joint_pose"/>
            <axis xyz="0 0 1" rpy="0 0 0" />
        </joint>
    </xacro:macro>

</robot>
